#VRML_SIM R2023b utf8

WorldInfo {
  basicTimeStep 16
  FPS 62.5
}
Viewpoint {
  orientation -0.2 0.9 0.3 1.2
  position 0.4 -0.35 0.55
}
DirectionalLight {
  direction -0.5 -1 -0.3
  intensity 1.2
}
Robot {
  translation 0 0 0.02
  children [
    HingeJoint {
      jointParameters HingeJointParameters {
        axis 0 0 1
        anchor 0 0 0.05
      }
      device [
        RotationalMotor {
          name "joint_motor"
          maxVelocity 15
          minPosition -0.2
          maxPosition 3.2
        }
        PositionSensor {
          name "joint_sensor"
        }
      ]
      endPoint Solid {
        translation 0 0 0.05
        children [
          Pose {
            translation 0.12 0 0
            children [
              Shape {
                appearance PbrAppearance {
                  baseColor 0.2 0.45 0.85
                  roughness 0.35
                  metalness 0
                }
                geometry Box { size 0.24 0.04 0.04 }
              }
            ]
          }
          Pose {
            translation 0.24 0 0
            children [
              TouchSensor {
                name "finger_touch"
                type "bumper"
                children [
                  Shape {
                    appearance PbrAppearance {
                      baseColor 0.9 0.75 0.2
                      roughness 0.5
                      metalness 0
                    }
                    geometry Sphere { radius 0.025 }
                  }
                ]
              }
            ]
          }
        ]
        boundingObject Pose {
          translation 0.12 0 0
          children [ Box { size 0.24 0.04 0.04 } ]
        }
        physics Physics { density -1 mass 0.08 }
      }
    }
  ]
  boundingObject Box { size 0.06 0.06 0.02 }
  physics Physics { density -1 mass 0.05 }
  controller "rehab_digital_twin"
  supervisor FALSE
}
Solid {
  translation 0.38 0 0.05
  children [
    Shape {
      appearance PbrAppearance {
        baseColor 1 0.25 0.25
        roughness 0.3
        metalness 0
      }
      geometry Sphere { radius 0.05 }
    }
  ]
  boundingObject Sphere { radius 0.05 }
  physics Physics { density -1 mass 0.1 }
}
